<?xml version="1.0" encoding="UTF-8"?>
<!-- Generated by org.testng.reporters.JUnitReportReporter -->
<testsuite skipped="0" hostname="PYTs-MacBook-Air.local" name="com.TestNG.Test_timeout" tests="3" failures="0" timestamp="2022-02-10T23:07:24 IST" time="1.049" errors="1">
  <testcase name="Second_Test" time="0.004" classname="com.TestNG.Test_timeout"/>
  <testcase name="Third_Test" time="0.002" classname="com.TestNG.Test_timeout"/>
  <testcase name="First_Test" time="1.043" classname="com.TestNG.Test_timeout">
    <error type="org.testng.internal.thread.ThreadTimeoutException" message="Method com.TestNG.Test_timeout.First_Test() didn&#039;t finish within the time-out 1000">
      <![CDATA[org.testng.internal.thread.ThreadTimeoutException: Method com.TestNG.Test_timeout.First_Test() didn't finish within the time-out 1000
at sun.misc.Unsafe.putOrderedInt(Native Method)
at java.util.concurrent.FutureTask.setException(FutureTask.java:250)
at java.util.concurrent.FutureTask.run(FutureTask.java:271)
at java.util.concurrent.ThreadPoolExecutor.runWorker(ThreadPoolExecutor.java:1149)
at java.util.concurrent.ThreadPoolExecutor$Worker.run(ThreadPoolExecutor.java:624)
at java.lang.Thread.run(Thread.java:750)
]]>
    </error>
  </testcase> <!-- First_Test -->
</testsuite> <!-- com.TestNG.Test_timeout -->
